[2025-05-12T08:38:15.016+0000] {local_task_job_runner.py:120} INFO - ::group::Pre task execution logs
[2025-05-12T08:38:15.043+0000] {taskinstance.py:2073} INFO - Dependencies all met for dep_context=non-requeueable deps ti=<TaskInstance: retrain_PWU_dag.train_PWU manual__2025-05-12T08:38:14.122872+00:00 [queued]>
[2025-05-12T08:38:15.050+0000] {taskinstance.py:2073} INFO - Dependencies all met for dep_context=requeueable deps ti=<TaskInstance: retrain_PWU_dag.train_PWU manual__2025-05-12T08:38:14.122872+00:00 [queued]>
[2025-05-12T08:38:15.051+0000] {taskinstance.py:2303} INFO - Starting attempt 1 of 1
[2025-05-12T08:38:15.063+0000] {taskinstance.py:2327} INFO - Executing <Task(BashOperator): train_PWU> on 2025-05-12 08:38:14.122872+00:00
[2025-05-12T08:38:15.069+0000] {standard_task_runner.py:90} INFO - Running: ['***', 'tasks', 'run', 'retrain_PWU_dag', 'train_PWU', 'manual__2025-05-12T08:38:14.122872+00:00', '--job-id', '30', '--raw', '--subdir', 'DAGS_FOLDER/retrain_PWU_dag.py', '--cfg-path', '/tmp/tmp3dvmwbk5']
[2025-05-12T08:38:15.071+0000] {standard_task_runner.py:91} INFO - Job 30: Subtask train_PWU
[2025-05-12T08:38:15.072+0000] {logging_mixin.py:188} WARNING - /home/***/.local/lib/python3.12/site-packages/***/task/task_runner/standard_task_runner.py:61 DeprecationWarning: This process (pid=345) is multi-threaded, use of fork() may lead to deadlocks in the child.
[2025-05-12T08:38:15.073+0000] {standard_task_runner.py:63} INFO - Started process 346 to run task
[2025-05-12T08:38:15.112+0000] {task_command.py:426} INFO - Running <TaskInstance: retrain_PWU_dag.train_PWU manual__2025-05-12T08:38:14.122872+00:00 [running]> on host b3690c8add92
[2025-05-12T08:38:15.185+0000] {taskinstance.py:2644} INFO - Exporting env vars: AIRFLOW_CTX_DAG_OWNER='***' AIRFLOW_CTX_DAG_ID='retrain_PWU_dag' AIRFLOW_CTX_TASK_ID='train_PWU' AIRFLOW_CTX_EXECUTION_DATE='2025-05-12T08:38:14.122872+00:00' AIRFLOW_CTX_TRY_NUMBER='1' AIRFLOW_CTX_DAG_RUN_ID='manual__2025-05-12T08:38:14.122872+00:00'
[2025-05-12T08:38:15.186+0000] {taskinstance.py:430} INFO - ::endgroup::
[2025-05-12T08:38:15.196+0000] {subprocess.py:63} INFO - Tmp dir root location: /tmp
[2025-05-12T08:38:15.197+0000] {subprocess.py:75} INFO - Running command: ['/usr/bin/bash', '-c', 'python /opt/***/scripts/train_PWU.py']
[2025-05-12T08:38:15.204+0000] {subprocess.py:86} INFO - Output:
[2025-05-12T13:23:10.169+0000] {local_task_job_runner.py:124} ERROR - Received SIGTERM. Terminating subprocesses
[2025-05-12T13:23:11.305+0000] {process_utils.py:132} INFO - Sending 15 to group 346. PIDs of all processes in the group: [347, 346]
[2025-05-12T13:23:11.339+0000] {process_utils.py:87} INFO - Sending the signal 15 to group 346
[2025-05-12T13:23:12.555+0000] {taskinstance.py:2607} ERROR - Received SIGTERM. Terminating subprocesses.
[2025-05-12T13:23:13.598+0000] {subprocess.py:104} INFO - Sending SIGTERM signal to process group
[2025-05-12T13:23:13.664+0000] {taskinstance.py:441} INFO - ::group::Post task execution logs
[2025-05-12T13:23:14.353+0000] {taskinstance.py:2890} ERROR - Task failed with exception
Traceback (most recent call last):
  File "/home/airflow/.local/lib/python3.12/site-packages/airflow/models/taskinstance.py", line 465, in _execute_task
    result = _execute_callable(context=context, **execute_callable_kwargs)
             ^^^^^^^^^^^^^^^^^^^^^^^^^^^^^^^^^^^^^^^^^^^^^^^^^^^^^^^^^^^^^
  File "/home/airflow/.local/lib/python3.12/site-packages/airflow/models/taskinstance.py", line 432, in _execute_callable
    return execute_callable(context=context, **execute_callable_kwargs)
           ^^^^^^^^^^^^^^^^^^^^^^^^^^^^^^^^^^^^^^^^^^^^^^^^^^^^^^^^^^^^
  File "/home/airflow/.local/lib/python3.12/site-packages/airflow/models/baseoperator.py", line 400, in wrapper
    return func(self, *args, **kwargs)
           ^^^^^^^^^^^^^^^^^^^^^^^^^^^
  File "/home/airflow/.local/lib/python3.12/site-packages/airflow/operators/bash.py", line 234, in execute
    result = self.subprocess_hook.run_command(
             ^^^^^^^^^^^^^^^^^^^^^^^^^^^^^^^^^
  File "/home/airflow/.local/lib/python3.12/site-packages/airflow/hooks/subprocess.py", line 91, in run_command
    for raw_line in iter(self.sub_process.stdout.readline, b""):
  File "/home/airflow/.local/lib/python3.12/site-packages/airflow/models/taskinstance.py", line 2609, in signal_handler
    raise AirflowTaskTerminated("Task received SIGTERM signal")
airflow.exceptions.AirflowTaskTerminated: Task received SIGTERM signal
[2025-05-12T13:23:14.443+0000] {taskinstance.py:1205} INFO - Marking task as FAILED. dag_id=retrain_PWU_dag, task_id=train_PWU, execution_date=20250512T083814, start_date=20250512T083815, end_date=20250512T132314
[2025-05-12T13:23:14.592+0000] {process_utils.py:80} INFO - Process psutil.Process(pid=346, status='terminated', exitcode=2, started='08:38:14') (346) terminated with exit code 2
[2025-05-12T13:23:14.595+0000] {process_utils.py:80} INFO - Process psutil.Process(pid=347, status='terminated', started='08:38:15') (347) terminated with exit code None
[2025-05-12T13:23:14.598+0000] {local_task_job_runner.py:240} INFO - Task exited with return code 143
[2025-05-12T13:23:14.761+0000] {taskinstance.py:3482} INFO - 0 downstream tasks scheduled from follow-on schedule check
[2025-05-12T13:23:14.795+0000] {local_task_job_runner.py:222} INFO - ::endgroup::
