[2025-05-13T03:40:50.565+0000] {local_task_job_runner.py:120} INFO - ::group::Pre task execution logs
[2025-05-13T03:40:50.593+0000] {taskinstance.py:2073} INFO - Dependencies all met for dep_context=non-requeueable deps ti=<TaskInstance: retrain_T3_dag.train_T3 manual__2025-05-13T03:40:50.219664+00:00 [queued]>
[2025-05-13T03:40:50.600+0000] {taskinstance.py:2073} INFO - Dependencies all met for dep_context=requeueable deps ti=<TaskInstance: retrain_T3_dag.train_T3 manual__2025-05-13T03:40:50.219664+00:00 [queued]>
[2025-05-13T03:40:50.600+0000] {taskinstance.py:2303} INFO - Starting attempt 1 of 1
[2025-05-13T03:40:50.614+0000] {taskinstance.py:2327} INFO - Executing <Task(BashOperator): train_T3> on 2025-05-13 03:40:50.219664+00:00
[2025-05-13T03:40:50.621+0000] {standard_task_runner.py:90} INFO - Running: ['***', 'tasks', 'run', 'retrain_T3_dag', 'train_T3', 'manual__2025-05-13T03:40:50.219664+00:00', '--job-id', '9', '--raw', '--subdir', 'DAGS_FOLDER/retrain_T3_dag.py', '--cfg-path', '/tmp/tmp59s7q7s7']
[2025-05-13T03:40:50.623+0000] {standard_task_runner.py:91} INFO - Job 9: Subtask train_T3
[2025-05-13T03:40:50.624+0000] {logging_mixin.py:188} WARNING - /home/***/.local/lib/python3.12/site-packages/***/task/task_runner/standard_task_runner.py:61 DeprecationWarning: This process (pid=279) is multi-threaded, use of fork() may lead to deadlocks in the child.
[2025-05-13T03:40:50.625+0000] {standard_task_runner.py:63} INFO - Started process 280 to run task
[2025-05-13T03:40:50.694+0000] {task_command.py:426} INFO - Running <TaskInstance: retrain_T3_dag.train_T3 manual__2025-05-13T03:40:50.219664+00:00 [running]> on host e27023c184cc
[2025-05-13T03:40:50.779+0000] {taskinstance.py:2644} INFO - Exporting env vars: AIRFLOW_CTX_DAG_OWNER='***' AIRFLOW_CTX_DAG_ID='retrain_T3_dag' AIRFLOW_CTX_TASK_ID='train_T3' AIRFLOW_CTX_EXECUTION_DATE='2025-05-13T03:40:50.219664+00:00' AIRFLOW_CTX_TRY_NUMBER='1' AIRFLOW_CTX_DAG_RUN_ID='manual__2025-05-13T03:40:50.219664+00:00'
[2025-05-13T03:40:50.780+0000] {taskinstance.py:430} INFO - ::endgroup::
[2025-05-13T03:40:50.791+0000] {subprocess.py:63} INFO - Tmp dir root location: /tmp
[2025-05-13T03:40:50.792+0000] {subprocess.py:75} INFO - Running command: ['/usr/bin/bash', '-c', 'python /opt/***/scripts/train_T3.py']
[2025-05-13T03:40:50.799+0000] {subprocess.py:86} INFO - Output:
[2025-05-13T03:40:55.907+0000] {subprocess.py:93} INFO - Traceback (most recent call last):
[2025-05-13T03:40:55.907+0000] {subprocess.py:93} INFO -   File "/opt/***/scripts/train_T3.py", line 48, in <module>
[2025-05-13T03:40:55.909+0000] {subprocess.py:93} INFO -     df[INPUT_COLS + [TARGET_COL]] = scaler.fit_transform(df[INPUT_COLS + [TARGET_COL]])
[2025-05-13T03:40:55.910+0000] {subprocess.py:93} INFO -                                                          ~~^^^^^^^^^^^^^^^^^^^^^^^^^^^
[2025-05-13T03:40:55.910+0000] {subprocess.py:93} INFO -   File "/home/***/.local/lib/python3.12/site-packages/pandas/core/frame.py", line 3899, in __getitem__
[2025-05-13T03:40:55.911+0000] {subprocess.py:93} INFO -     indexer = self.columns._get_indexer_strict(key, "columns")[1]
[2025-05-13T03:40:55.911+0000] {subprocess.py:93} INFO -               ^^^^^^^^^^^^^^^^^^^^^^^^^^^^^^^^^^^^^^^^^^^^^^^^
[2025-05-13T03:40:55.911+0000] {subprocess.py:93} INFO -   File "/home/***/.local/lib/python3.12/site-packages/pandas/core/indexes/base.py", line 6115, in _get_indexer_strict
[2025-05-13T03:40:55.912+0000] {subprocess.py:93} INFO -     self._raise_if_missing(keyarr, indexer, axis_name)
[2025-05-13T03:40:55.912+0000] {subprocess.py:93} INFO -   File "/home/***/.local/lib/python3.12/site-packages/pandas/core/indexes/base.py", line 6179, in _raise_if_missing
[2025-05-13T03:40:55.913+0000] {subprocess.py:93} INFO -     raise KeyError(f"{not_found} not in index")
[2025-05-13T03:40:55.913+0000] {subprocess.py:93} INFO - KeyError: "['T3'] not in index"
[2025-05-13T03:40:56.833+0000] {subprocess.py:97} INFO - Command exited with return code 1
[2025-05-13T03:40:56.834+0000] {taskinstance.py:441} INFO - ::group::Post task execution logs
[2025-05-13T03:40:56.844+0000] {taskinstance.py:2890} ERROR - Task failed with exception
Traceback (most recent call last):
  File "/home/airflow/.local/lib/python3.12/site-packages/airflow/models/taskinstance.py", line 465, in _execute_task
    result = _execute_callable(context=context, **execute_callable_kwargs)
             ^^^^^^^^^^^^^^^^^^^^^^^^^^^^^^^^^^^^^^^^^^^^^^^^^^^^^^^^^^^^^
  File "/home/airflow/.local/lib/python3.12/site-packages/airflow/models/taskinstance.py", line 432, in _execute_callable
    return execute_callable(context=context, **execute_callable_kwargs)
           ^^^^^^^^^^^^^^^^^^^^^^^^^^^^^^^^^^^^^^^^^^^^^^^^^^^^^^^^^^^^
  File "/home/airflow/.local/lib/python3.12/site-packages/airflow/models/baseoperator.py", line 400, in wrapper
    return func(self, *args, **kwargs)
           ^^^^^^^^^^^^^^^^^^^^^^^^^^^
  File "/home/airflow/.local/lib/python3.12/site-packages/airflow/operators/bash.py", line 243, in execute
    raise AirflowException(
airflow.exceptions.AirflowException: Bash command failed. The command returned a non-zero exit code 1.
[2025-05-13T03:40:56.849+0000] {taskinstance.py:1205} INFO - Marking task as FAILED. dag_id=retrain_T3_dag, task_id=train_T3, execution_date=20250513T034050, start_date=20250513T034050, end_date=20250513T034056
[2025-05-13T03:40:56.865+0000] {standard_task_runner.py:110} ERROR - Failed to execute job 9 for task train_T3 (Bash command failed. The command returned a non-zero exit code 1.; 280)
[2025-05-13T03:40:56.875+0000] {local_task_job_runner.py:240} INFO - Task exited with return code 1
[2025-05-13T03:40:56.896+0000] {taskinstance.py:3482} INFO - 0 downstream tasks scheduled from follow-on schedule check
[2025-05-13T03:40:56.901+0000] {local_task_job_runner.py:222} INFO - ::endgroup::
