[2025-05-21T17:27:59.709+0000] {local_task_job_runner.py:120} INFO - ::group::Pre task execution logs
[2025-05-21T17:27:59.761+0000] {taskinstance.py:2073} INFO - Dependencies all met for dep_context=non-requeueable deps ti=<TaskInstance: monitor_T3.monitor_model manual__2025-05-21T17:27:58.544147+00:00 [queued]>
[2025-05-21T17:27:59.774+0000] {taskinstance.py:2073} INFO - Dependencies all met for dep_context=requeueable deps ti=<TaskInstance: monitor_T3.monitor_model manual__2025-05-21T17:27:58.544147+00:00 [queued]>
[2025-05-21T17:27:59.775+0000] {taskinstance.py:2303} INFO - Starting attempt 1 of 1
[2025-05-21T17:27:59.809+0000] {taskinstance.py:2327} INFO - Executing <Task(PythonOperator): monitor_model> on 2025-05-21 17:27:58.544147+00:00
[2025-05-21T17:27:59.820+0000] {standard_task_runner.py:90} INFO - Running: ['***', 'tasks', 'run', 'monitor_T3', 'monitor_model', 'manual__2025-05-21T17:27:58.544147+00:00', '--job-id', '43', '--raw', '--subdir', 'DAGS_FOLDER/monitor_T3.py', '--cfg-path', '/tmp/tmpvqsk3b22']
[2025-05-21T17:27:59.824+0000] {standard_task_runner.py:91} INFO - Job 43: Subtask monitor_model
[2025-05-21T17:27:59.829+0000] {logging_mixin.py:188} WARNING - /home/***/.local/lib/python3.12/site-packages/***/task/task_runner/standard_task_runner.py:61 DeprecationWarning: This process (pid=244) is multi-threaded, use of fork() may lead to deadlocks in the child.
[2025-05-21T17:27:59.831+0000] {standard_task_runner.py:63} INFO - Started process 246 to run task
[2025-05-21T17:27:59.906+0000] {task_command.py:426} INFO - Running <TaskInstance: monitor_T3.monitor_model manual__2025-05-21T17:27:58.544147+00:00 [running]> on host ddb70be9709c
[2025-05-21T17:28:00.081+0000] {taskinstance.py:2644} INFO - Exporting env vars: AIRFLOW_CTX_DAG_OWNER='***' AIRFLOW_CTX_DAG_ID='monitor_T3' AIRFLOW_CTX_TASK_ID='monitor_model' AIRFLOW_CTX_EXECUTION_DATE='2025-05-21T17:27:58.544147+00:00' AIRFLOW_CTX_TRY_NUMBER='1' AIRFLOW_CTX_DAG_RUN_ID='manual__2025-05-21T17:27:58.544147+00:00'
[2025-05-21T17:28:00.082+0000] {taskinstance.py:430} INFO - ::endgroup::
[2025-05-21T17:28:00.151+0000] {taskinstance.py:441} INFO - ::group::Post task execution logs
[2025-05-21T17:28:00.152+0000] {taskinstance.py:2890} ERROR - Task failed with exception
Traceback (most recent call last):
  File "/home/airflow/.local/lib/python3.12/site-packages/airflow/models/taskinstance.py", line 465, in _execute_task
    result = _execute_callable(context=context, **execute_callable_kwargs)
             ^^^^^^^^^^^^^^^^^^^^^^^^^^^^^^^^^^^^^^^^^^^^^^^^^^^^^^^^^^^^^
  File "/home/airflow/.local/lib/python3.12/site-packages/airflow/models/taskinstance.py", line 432, in _execute_callable
    return execute_callable(context=context, **execute_callable_kwargs)
           ^^^^^^^^^^^^^^^^^^^^^^^^^^^^^^^^^^^^^^^^^^^^^^^^^^^^^^^^^^^^
  File "/home/airflow/.local/lib/python3.12/site-packages/airflow/models/baseoperator.py", line 400, in wrapper
    return func(self, *args, **kwargs)
           ^^^^^^^^^^^^^^^^^^^^^^^^^^^
  File "/home/airflow/.local/lib/python3.12/site-packages/airflow/operators/python.py", line 235, in execute
    return_value = self.execute_callable()
                   ^^^^^^^^^^^^^^^^^^^^^^^
  File "/home/airflow/.local/lib/python3.12/site-packages/airflow/operators/python.py", line 252, in execute_callable
    return self.python_callable(*self.op_args, **self.op_kwargs)
           ^^^^^^^^^^^^^^^^^^^^^^^^^^^^^^^^^^^^^^^^^^^^^^^^^^^^^
  File "/opt/airflow/dags/monitor_T3.py", line 26, in monitor_model
    raise Exception(f"Flask prediction failed.\nStatus: {res.status_code}\nMessage: {res.text}")
Exception: Flask prediction failed.
Status: 500
Message: {"error":"[Errno 2] No such file or directory: '/app/scaler/x_t3_scaler.pkl'"}

[2025-05-21T17:28:00.169+0000] {taskinstance.py:1205} INFO - Marking task as FAILED. dag_id=monitor_T3, task_id=monitor_model, execution_date=20250521T172758, start_date=20250521T172759, end_date=20250521T172800
[2025-05-21T17:28:00.191+0000] {standard_task_runner.py:110} ERROR - Failed to execute job 43 for task monitor_model (Flask prediction failed.
Status: 500
Message: {"error":"[Errno 2] No such file or directory: '/app/scaler/x_t3_scaler.pkl'"}
; 246)
[2025-05-21T17:28:00.208+0000] {local_task_job_runner.py:240} INFO - Task exited with return code 1
[2025-05-21T17:28:00.244+0000] {taskinstance.py:3482} INFO - 0 downstream tasks scheduled from follow-on schedule check
[2025-05-21T17:28:00.252+0000] {local_task_job_runner.py:222} INFO - ::endgroup::
